<?xml version="1.0" encoding="utf-8"?>
  <!-- This URDF was automatically created by SolidWorks to URDF Exporter! Originally created by Stephen Brawner (brawner@gmail.com) 
       Commit Version: 1.6.0-4-g7f85cfe  Build Version: 1.6.7995.38578
       For more information, please see http://wiki.ros.org/sw_urdf_exporter -->
  <robot name="xlerobot_ht_description">
   <mujoco>
     <compiler meshdir="../meshes/" balanceinertia="true" discardvisual="false" />
   </mujoco>
 
    <link name="base_link">
      <inertial>
        <origin xyz="-6.7e-06 -6.477e-05 0.01798916" rpy="0 0 0" />
        <mass value="0.48888809" />
        <inertia ixx="0.00040573" ixy="-2.4e-07" ixz="4.8e-07" iyy="0.00043007" iyz="4.2e-07" izz="0.00059661" />
      </inertial>
      <visual>
        <origin xyz="0 0 0" rpy="0 0 0" />
        <geometry>
          <mesh filename="package://xlerobot_ht_description/meshes/base_link.STL" />
        </geometry>
        <material name="">
          <color rgba="0.75294 0.75294 0.75294 1" />
        </material>
      </visual>
      <collision>
        <origin xyz="0 0 0" rpy="0 0 0" />
        <geometry>
          <mesh filename="package://xlerobot_ht_description/meshes/base_link.STL" />
        </geometry>
      </collision>
    </link>
    <link name="link1">
      <inertial>
        <origin xyz="0.00093765 -0.0003632 0.01772447" rpy="0 0 0" />
        <mass value="0.11213854" />
        <inertia ixx="8.77e-05" ixy="4.9e-07" ixz="-6.96e-06" iyy="4.584e-05" iyz="9.3e-07" izz="8.407e-05" />
      </inertial>
      <visual>
        <origin xyz="0 0 0" rpy="0 0 0" />
        <geometry>
          <mesh filename="package://xlerobot_ht_description/meshes/link1.STL" />
        </geometry>
        <material name="">
          <color rgba="0.75294 0.75294 0.75294 1" />
        </material>
      </visual>
      <collision>
        <origin xyz="0 0 0" rpy="0 0 0" />
        <geometry>
          <mesh filename="package://xlerobot_ht_description/meshes/link1.STL" />
        </geometry>
      </collision>
    </link>
    <joint name="joint1" type="revolute">
      <origin xyz="0 0 0.0509" rpy="0 0 0" />
      <parent link="base_link" />
      <child link="link1" />
      <axis xyz="0 0 1" />
      <limit lower="-2.4" upper="2.4" effort="10" velocity="36" />
    </joint>
    <link name="link2">
      <inertial>
        <origin xyz="-0.07697407 -0.00343256 0.00025998" rpy="0 0 0" />
        <mass value="0.5508467" />
        <inertia ixx="0.00012156" ixy="-0.00000575" ixz="-0.00001053" iyy="0.00298168" iyz="-0.00000077" izz="0.00302744" />
      </inertial>
      <visual>
        <origin xyz="0 0 0" rpy="0 0 0" />
        <geometry>
          <mesh filename="package://xlerobot_ht_description/meshes/link2.STL" />
        </geometry>
        <material name="">
          <color rgba="0.75294 0.75294 0.75294 1" />
        </material>
      </visual>
      <collision>
        <origin xyz="0 0 0" rpy="0 0 0" />
        <geometry>
          <mesh filename="package://xlerobot_ht_description/meshes/link2.STL" />
        </geometry>
      </collision>
    </link>
    <joint name="joint2" type="revolute">
      <origin xyz="0.014559 0 0.043" rpy="0 0 0" />
      <parent link="link1" />
      <child link="link2" />
      <axis xyz="0 1 0" />
      <limit lower="0" upper="3.4" effort="10" velocity="36" />
    </joint>
    <link name="link3">
      <inertial>
        <origin xyz="0.07 -0.00283703 0.04500842" rpy="0 0 0" />
        <mass value="0.20" />
        <inertia ixx="0.00016726" ixy="0.00002980" ixz="-0.00017218" iyy="0.00094995" iyz="0.00000440" izz="0.00094438" />
      </inertial>
      <visual>
        <origin xyz="0 0 0" rpy="0 0 0" />
        <geometry>
          <mesh filename="package://xlerobot_ht_description/meshes/link3.STL" />
        </geometry>
        <material name="">
          <color rgba="0.75294 0.75294 0.75294 1" />
        </material>
      </visual>
      <collision>
        <origin xyz="0 0 0" rpy="0 0 0" />
        <geometry>
          <mesh filename="package://xlerobot_ht_description/meshes/link3.STL" />
        </geometry>
      </collision>
    </link>
    <joint name="joint3" type="revolute">
      <origin xyz="-0.156 0 0" rpy="0 0 0" />
      <parent link="link2" />
      <child link="link3" />
      <axis xyz="0 -1 0" />
      <limit lower="0" upper="3.4" effort="10" velocity="36" />
    </joint>
    <link name="link4">
      <inertial>
        <origin xyz="0.04660916 -4.35e-05 0.03826516" rpy="0 0 0" />
        <mass value="0.194896" />
        <inertia ixx="0.00008403" ixy="0.00000039" ixz="-0.00005214" iyy="0.00011718" iyz="0.00000047" izz="0.00010438" />
      </inertial>
      <visual>
        <origin xyz="0 0 0" rpy="0 0 0" />
        <geometry>
          <mesh filename="package://xlerobot_ht_description/meshes/link4.STL" />
        </geometry>
        <material name="">
          <color rgba="0.75294 0.75294 0.75294 1" />
        </material>
      </visual>
      <collision>
        <origin xyz="0 0 0" rpy="0 0 0" />
        <geometry>
          <mesh filename="package://xlerobot_ht_description/meshes/link4.STL" />
        </geometry>
      </collision>
    </link>
    <joint name="joint4" type="revolute">
      <origin xyz="0.138 0 0.05" rpy="0 0 0" />
      <parent link="link3" />
      <child link="link4" />
      <axis xyz="0 -1 0" />
      <limit lower="-1.7" upper="1.7" effort="10" velocity="36" />
    </joint>
    <link name="link5">
      <inertial>
        <origin xyz="0.00285059 -9.067e-05 -0.02985903" rpy="0 0 0" />
        <mass value="0.17547184" />
        <inertia ixx="2.152e-05" ixy="0.0" ixz="0.0" iyy="2.409e-05" iyz="1.55e-06" izz="-7e-08" />
      </inertial>
      <visual>
        <origin xyz="0 0 0" rpy="0 0 0" />
        <geometry>
          <mesh filename="package://xlerobot_ht_description/meshes/link5.STL" />
        </geometry>
        <material name="">
          <color rgba="0.75294 0.75294 0.75294 1" />
        </material>
      </visual>
      <collision>
        <origin xyz="0 0 0" rpy="0 0 0" />
        <geometry>
          <mesh filename="package://xlerobot_ht_description/meshes/link5.STL" />
        </geometry>
      </collision>
    </link>
    <joint name="joint5" type="revolute">
      <origin xyz="0.055 0 0.030878" rpy="0 0 0" />
      <parent link="link4" />
      <child link="link5" />
      <axis xyz="0 0 -1" />
      <limit lower="-1.7" upper="1.7" effort="3.7" velocity="60" />
    </joint>
   <link name="link6">
     <inertial>
       <origin xyz="0.00491171194554647 3.24724189844782E-12 0.000236602402152258" rpy="0 0 0" />
       <mass value="0.0123808389352235" />
       <inertia ixx="9.44576753568983E-07" ixy="-3.07532048036139E-17" ixz="-9.06869357885819E-10" iyy="6.41459660763183E-07" iyz="4.1681110231471E-16" izz="5.96432193039218E-07" />
     </inertial>
     <visual>
       <origin xyz="0 0 0" rpy="0 0 0" />
       <geometry>
         <mesh filename="package://xlerobot_ht_description/meshes/link6.STL" />
       </geometry>
       <material name="">
         <color rgba="0.752941176470588 0.752941176470588 0.752941176470588 1" />
       </material>
     </visual>
     <collision>
       <origin xyz="0 0 0" rpy="0 0 0" />
       <geometry>
         <mesh filename="package://xlerobot_ht_description/meshes/link6.STL" />
       </geometry>
     </collision>
   </link>
   <joint name="joint6" type="revolute">
     <origin xyz="0.0185999999999977 0 -0.0330000000000016" rpy="0 0 0" />
     <parent link="link5" />
     <child link="link6" />
     <axis xyz="1 0 0" />
     <limit lower="-3.14" upper="3.14" effort="3.7" velocity="60" />
   </joint>
      <link name="L_finger">
     <inertial>
       <origin xyz="-0.0665513053307253 0.0168637833221042 -0.000510235194076225" rpy="0 0 0" />
       <mass value="0.127457990511979" />
       <inertia ixx="2.28803355389149E-05" ixy="-4.20099870615684E-06" ixz="3.42841892362126E-07" iyy="5.15650351903207E-05" iyz="-5.67310158184507E-10" izz="4.6498598079908E-05" />
     </inertial>
     <visual>
       <origin xyz="0 0 0" rpy="0 0 0" />
       <geometry>
         <mesh filename="package://xlerobot_ht_description/meshes/L_finger.STL" />
       </geometry>
       <material name="">
         <color rgba="0.752941176470588 0.752941176470588 0.752941176470588 1" />
       </material>
     </visual>
     <collision>
       <origin xyz="0 0 0" rpy="0 0 0" />
       <geometry>
         <mesh filename="package://xlerobot_ht_description/meshes/L_finger.STL" />
       </geometry>
     </collision>
   </link>
   <joint name="L_finger_joint" type="prismatic">
     <origin xyz="0.165 0 0" rpy="0 0 0" />
     <parent link="link6" />
     <child link="L_finger" />
     <axis xyz="0 1 0" />
     <limit lower="0" upper="0.04" effort="0" velocity="0" />
   </joint>
   <link name="R_finger">
     <inertial>
       <origin xyz="-0.0665513053302189 -0.0168637833220831 0.000510464525271231" rpy="0 0 0" />
       <mass value="0.127457990512492" />
       <inertia ixx="2.28803355388256E-05" ixy="4.20099870624986E-06" ixz="-3.42841892601057E-07" iyy="5.15650351948177E-05" iyz="-5.67310171384371E-10" izz="4.64985980845201E-05" />
     </inertial>
     <visual>
       <origin xyz="0 0 0" rpy="0 0 0" />
       <geometry>
         <mesh filename="package://xlerobot_ht_description/meshes/R_finger.STL" />
       </geometry>
       <material name="">
         <color rgba="0.752941176470588 0.752941176470588 0.752941176470588 1" />
       </material>
     </visual>
     <collision>
       <origin xyz="0 0 0" rpy="0 0 0" />
       <geometry>
         <mesh filename="package://xlerobot_ht_description/meshes/R_finger.STL" />
       </geometry>
     </collision>
   </link>
   <joint name="R_finger_joint" type="prismatic">
     <origin xyz="0.165 0 0" rpy="0 0 0" />
     <parent link="link6" />
     <child link="R_finger" />
     <axis xyz="0 -1 0" />
     <limit lower="0" upper="0.04" effort="0" velocity="0" />
     <mimic joint="L_finger_joint" multiplier="1" offset="0" />
   </joint>
   <link name="gripper_center">
     <inertial>
       <origin xyz="-0.123183748651091 -4.83923293203893E-05 -3.75244690079823E-05" rpy="0 0 0" />
       <mass value="0.0969304971507011" />
       <inertia ixx="9.06334704672063E-05" ixy="2.21890810267114E-09" ixz="-4.10704620371571E-09" iyy="1.13202586691018E-05" iyz="4.83663479833145E-08" izz="8.43793149524868E-05" />
     </inertial>
     <visual>
       <origin xyz="0 0 0" rpy="0 0 0" />
       <geometry>
         <mesh filename="package://xlerobot_ht_description/meshes/gripper_center.STL" />
       </geometry>
       <material name="">
         <color rgba="0.866666666666667 0.909803921568627 1 1" />
       </material>
     </visual>
     <collision>
       <origin xyz="0 0 0" rpy="0 0 0" />
       <geometry>
         <mesh filename="package://xlerobot_ht_description/meshes/gripper_center.STL" />
       </geometry>
     </collision>
   </link>
   <joint name="gripper_center_joint" type="fixed">
     <origin xyz="0.165 0 0" rpy="0 0 0" />
     <parent link="link6" />
     <child link="gripper_center" />
     <axis xyz="0 0 0" />
   </joint>
 </robot>