<?xml version="1.0" encoding="utf-8"?>
 <!-- This URDF was automatically created by SolidWorks to URDF Exporter! Originally created by Stephen Brawner (brawner@gmail.com) 
      Commit Version: 1.6.0-4-g7f85cfe  Build Version: 1.6.7995.38578
      For more information, please see http://wiki.ros.org/sw_urdf_exporter -->
 <robot name="xlerobot_ht_description">
  <mujoco>
    <compiler meshdir="../meshes/" balanceinertia="true" discardvisual="false" />
  </mujoco>

   <link name="base_link">
     <inertial>
       <origin xyz="-6.7e-06 -6.477e-05 0.01798916" rpy="0 0 0" />
       <mass value="0.48888809" />
       <inertia ixx="0.00040573" ixy="-2.4e-07" ixz="4.8e-07" iyy="0.00043007" iyz="4.2e-07" izz="0.00059661" />
     </inertial>
     <visual>
       <origin xyz="0 0 0" rpy="0 0 0" />
       <geometry>
         <mesh filename="package://xlerobot_ht_description/meshes/base_link.STL" />
       </geometry>
       <material name="">
         <color rgba="0.75294 0.75294 0.75294 1" />
       </material>
     </visual>
     <collision>
       <origin xyz="0 0 0" rpy="0 0 0" />
       <geometry>
         <mesh filename="package://xlerobot_ht_description/meshes/base_link.STL" />
       </geometry>
     </collision>
   </link>
   <link name="link1">
     <inertial>
       <origin xyz="0.00093765 -0.0003632 0.01772447" rpy="0 0 0" />
       <mass value="0.11213854" />
       <inertia ixx="8.77e-05" ixy="4.9e-07" ixz="-6.96e-06" iyy="4.584e-05" iyz="9.3e-07" izz="8.407e-05" />
     </inertial>
     <visual>
       <origin xyz="0 0 0" rpy="0 0 0" />
       <geometry>
         <mesh filename="package://xlerobot_ht_description/meshes/link1.STL" />
       </geometry>
       <material name="">
         <color rgba="0.75294 0.75294 0.75294 1" />
       </material>
     </visual>
     <collision>
       <origin xyz="0 0 0" rpy="0 0 0" />
       <geometry>
         <mesh filename="package://xlerobot_ht_description/meshes/link1.STL" />
       </geometry>
     </collision>
   </link>
   <joint name="joint1" type="revolute">
     <origin xyz="0 0 0.0509" rpy="0 0 0" />
     <parent link="base_link" />
     <child link="link1" />
     <axis xyz="0 0 1" />
     <limit lower="-2.4" upper="2.4" effort="10" velocity="36" />
   </joint>
   <link name="link2">
     <inertial>
       <origin xyz="-0.07697407 -0.00343256 0.00025998" rpy="0 0 0" />
       <mass value="0.5508467" />
       <inertia ixx="0.00012809" ixy="0.0001513" ixz="0.0" iyy="0.00624549" iyz="2e-07" izz="0.0062977" />
     </inertial>
     <visual>
       <origin xyz="0 0 0" rpy="0 0 0" />
       <geometry>
         <mesh filename="package://xlerobot_ht_description/meshes/link2.STL" />
       </geometry>
       <material name="">
         <color rgba="0.75294 0.75294 0.75294 1" />
       </material>
     </visual>
     <collision>
       <origin xyz="0 0 0" rpy="0 0 0" />
       <geometry>
         <mesh filename="package://xlerobot_ht_description/meshes/link2.STL" />
       </geometry>
     </collision>
   </link>
   <joint name="joint2" type="revolute">
     <origin xyz="0.014559 0 0.043" rpy="0 0 0" />
     <parent link="link1" />
     <child link="link2" />
     <axis xyz="0 1 0" />
     <limit lower="0" upper="3.4" effort="10" velocity="36" />
   </joint>
   <link name="link3">
     <inertial>
       <origin xyz="0.07 -0.00283703 0.04500842" rpy="0 0 0" />
       <mass value="0.20" />
       <inertia ixx="0.00087053" ixy="0.00013406" ixz="0.00013406" iyy="0.00555656" iyz="0.00182632" izz="4.855e-05" />
     </inertial>
     <visual>
       <origin xyz="0 0 0" rpy="0 0 0" />
       <geometry>
         <mesh filename="package://xlerobot_ht_description/meshes/link3.STL" />
       </geometry>
       <material name="">
         <color rgba="0.75294 0.75294 0.75294 1" />
       </material>
     </visual>
     <collision>
       <origin xyz="0 0 0" rpy="0 0 0" />
       <geometry>
         <mesh filename="package://xlerobot_ht_description/meshes/link3.STL" />
       </geometry>
     </collision>
   </link>
   <joint name="joint3" type="revolute">
     <origin xyz="-0.156 0 0" rpy="0 0 0" />
     <parent link="link2" />
     <child link="link3" />
     <axis xyz="0 -1 0" />
     <limit lower="0" upper="3.4" effort="10" velocity="36" />
   </joint>
   <link name="link4">
     <inertial>
       <origin xyz="0.04660916 -4.35e-05 0.03826516" rpy="0 0 0" />
       <mass value="0.194896" />
       <inertia ixx="0.0003694" ixy="7.9e-07" ixz="7.9e-07" iyy="0.00082595" iyz="0.00039974" izz="7.9e-07" />
     </inertial>
     <visual>
       <origin xyz="0 0 0" rpy="0 0 0" />
       <geometry>
         <mesh filename="package://xlerobot_ht_description/meshes/link4.STL" />
       </geometry>
       <material name="">
         <color rgba="0.75294 0.75294 0.75294 1" />
       </material>
     </visual>
     <collision>
       <origin xyz="0 0 0" rpy="0 0 0" />
       <geometry>
         <mesh filename="package://xlerobot_ht_description/meshes/link4.STL" />
       </geometry>
     </collision>
   </link>
   <joint name="joint4" type="revolute">
     <origin xyz="0.138 0 0.05" rpy="0 0 0" />
     <parent link="link3" />
     <child link="link4" />
     <axis xyz="0 -1 0" />
     <limit lower="-1.7" upper="1.7" effort="10" velocity="36" />
   </joint>
   <link name="link5">
     <inertial>
       <origin xyz="0.00285059 -9.067e-05 -0.02985903" rpy="0 0 0" />
       <mass value="0.17547184" />
       <inertia ixx="2.152e-05" ixy="0.0" ixz="0.0" iyy="2.409e-05" iyz="1.55e-06" izz="-7e-08" />
     </inertial>
     <visual>
       <origin xyz="0 0 0" rpy="0 0 0" />
       <geometry>
         <mesh filename="package://xlerobot_ht_description/meshes/link5.STL" />
       </geometry>
       <material name="">
         <color rgba="0.75294 0.75294 0.75294 1" />
       </material>
     </visual>
     <collision>
       <origin xyz="0 0 0" rpy="0 0 0" />
       <geometry>
         <mesh filename="package://xlerobot_ht_description/meshes/link5.STL" />
       </geometry>
     </collision>
   </link>
   <joint name="joint5" type="revolute">
     <origin xyz="0.055 0 0.030878" rpy="0 0 0" />
     <parent link="link4" />
     <child link="link5" />
     <axis xyz="0 0 -1" />
     <limit lower="-1.7" upper="1.7" effort="3.7" velocity="60" />
   </joint>
   <link name="link6">
     <inertial>
       <origin xyz="0.06887692 -3.065e-05 1.176e-05" rpy="0 0 0" />
       <mass value="0.3" />
       <inertia ixx="0.00104999" ixy="-5.6e-07" ixz="-5.6e-07" iyy="0.00069828" iyz="1.4e-07" izz="3.038e-05" />
     </inertial>
     <visual>
       <origin xyz="0 0 0" rpy="0 0 0" />
       <geometry>
         <mesh filename="package://xlerobot_ht_description/meshes/link6.STL" />
       </geometry>
       <material name="">
         <color rgba="0.75294 0.75294 0.75294 1" />
       </material>
     </visual>
     <collision>
       <origin xyz="0 0 0" rpy="0 0 0" />
       <geometry>
         <mesh filename="package://xlerobot_ht_description/meshes/link6.STL" />
       </geometry>
     </collision>
   </link>
   <joint name="joint6" type="revolute">
     <origin xyz="0.0186 0 -0.033" rpy="0 0 0" />
     <parent link="link5" />
     <child link="link6" />
     <axis xyz="1 0 0" />
     <limit lower="-3.14" upper="3.14" effort="3.7" velocity="60" />
   </joint>
   <link name="tool_link"/>
   <joint name="tool_joint" type="fixed">
     <origin xyz="0.165 0 0" rpy="0 0 0" />
     <parent link="link6" />
     <child link="tool_link" />
   </joint>
 </robot>